Workbook

Sheet Summary
A1: SQL Analysis of Customer Orders: Amazon India
A2: Source: Kaggle Amazon Sales Dataset (CC BY-NC-SA 4.0). Orders and revenue are review-based proxies; see Notes before quoting any number.
A4: Headline numbers
A5: Orders (reviews) | C5: Customers | E5: Products ordered | G5: Revenue (₹ lakh) | I5: Avg order value (₹) | K5: Repeat customers
A6: =Revenue!A6 -> 9269 | C6: =Revenue!B6 -> 9050 | E6: =Revenue!C6 -> 1184 | G6: =Revenue!D6/100000 -> 233.07702 | I6: =Revenue!E6 -> 2514.5865 | K6: =Customers!E6 -> 0.022320442
A8: Key findings
A9: ="1. Electronics brings in "&TEXT(Revenue!E10,"0.0%")&" of review-based revenue from only "&TEXT(Revenue!F10,"0.0%")&" of orders (average order ₹"&TEXT(Revenue!G10,"#,##0")&"); Computers & Accessories is "&TEXT(Revenue!F12,"0.0%")&" of orders but only "&TEXT(Revenue!E12,"0.0%")&" of revenue." -> 1. Electronics brings in 53.7% of review-based revenue from only 31.5% of orders (average order ₹4,288); Computers & Accessories is 27.4% of orders but only 10.9% of revenue.
A10: ="2. Orders of ₹10,000 or more are just "&TEXT(Revenue!D28,"0.0%")&" of orders but "&TEXT(Revenue!E28,"0.0%")&" of revenue; orders under ₹500 are "&TEXT(Revenue!D25,"0.0%")&" of orders and only "&TEXT(Revenue!E25,"0.0%")&" of revenue." -> 2. Orders of ₹10,000 or more are just 5.2% of orders but 44.7% of revenue; orders under ₹500 are 37.7% of orders and only 4.3% of revenue.
A11: ="3. Repeat customers (2+ orders) are only "&TEXT(Customers!E6,"0.0%")&" of customers and "&TEXT(Customers!G6,"0.0%")&" of revenue, but each spends about "&TEXT(Customers!H6/Customers!H7,"0.0")&"x a one-time customer (₹"&TEXT(Customers!H6,"#,##0")&" vs ₹"&TEXT(Customers!H7,"#,##0")&")." -> 3. Repeat customers (2+ orders) are only 2.2% of customers and 4.2% of revenue, but each spends about 1.9x a one-time customer (₹4,872 vs ₹2,523).
A12: ="4. Cross-selling is rare: only "&TEXT(Customers!C22,"0.0%")&" of customers bought from more than one main category." -> 4. Cross-selling is rare: only 1.2% of customers bought from more than one main category.
A13: ="5. The most-rated product is "&LEFT(Products!B6,38)&"... with "&TEXT(Products!H6,"#,##0")&" ratings, and "&COUNTIF(Products!E6:E15,"<1300")&" of the top 10 by ratings cost under ₹1,300 (cables, earphones, memory, a kitchen chopper)." -> 5. The most-rated product is Amazon Basics High-Speed HDMI Cable, 6... with 426,973 ratings, and 9 of the top 10 by ratings cost under ₹1,300 (cables, earphones, memory, a kitchen chopper).
A14: ="6. Weighting by ratings x price instead, Electronics is "&TEXT(Products!F34,"0.0%")&" of estimated revenue, driven by smartphones and smart TVs." -> 6. Weighting by ratings x price instead, Electronics is 70.4% of estimated revenue, driven by smartphones and smart TVs.

Sheet Revenue
A1: Revenue
A2: Orders = distinct customer reviews (a stand-in for purchases). Revenue = selling price of those items. Blue = values from SQL; black = formulas.
A4: Overview (query q01)
A5: Orders | B5: Customers | C5: Products ordered | D5: Revenue (₹) | E5: Avg order value (₹) | F5: Discount given (₹)
A6: 9269 | B6: 9050 | C6: 1184 | D6: 23307702 | E6: =D6/A6 -> 2514.5865 | F6: 18908404
A8: Revenue by main category (query q02)
A9: Main category | B9: Orders | C9: Customers | D9: Revenue (₹) | E9: Revenue share | F9: Order share | G9: Avg order value (₹)
A10: Electronics | B10: 2920 | C10: 2891 | D10: 12520592 | E10: =D10/D$19 -> 0.53718692 | F10: =B10/B$19 -> 0.31502859 | G10: =D10/B10 -> 4287.874
A11: Home & Kitchen | B11: 3513 | C11: 3480 | D11: 8126551 | E11: =D11/D$19 -> 0.34866377 | F11: =B11/B$19 -> 0.37900529 | G11: =D11/B11 -> 2313.2795
A12: Computers & Accessories | B12: 2536 | C12: 2490 | D12: 2546658 | E12: =D12/D$19 -> 0.10926251 | F12: =B12/B$19 -> 0.27360017 | G12: =D12/B12 -> 1004.2027
A13: Office Products | B13: 248 | C13: 245 | D13: 74792 | E13: =D13/D$19 -> 0.0032088965 | F13: =B13/B$19 -> 0.026755853 | G13: =D13/B13 -> 301.58065
A14: Car & Motorbike | B14: 8 | C14: 8 | D14: 18712 | E14: =D14/D$19 -> 0.00080282478 | F14: =B14/B$19 -> 0.00086309203 | G14: =D14/B14 -> 2339
A15: Musical Instruments | B15: 16 | C15: 16 | D15: 10208 | E15: =D15/D$19 -> 0.00043796683 | F15: =B15/B$19 -> 0.0017261841 | G15: =D15/B15 -> 638
A16: Home Improvement | B16: 16 | C16: 16 | D16: 5392 | E16: =D16/D$19 -> 0.00023133985 | F16: =B16/B$19 -> 0.0017261841 | G16: =D16/B16 -> 337
A17: Health & Personal Care | B17: 4 | C17: 4 | D17: 3596 | E17: =D17/D$19 -> 0.00015428377 | F17: =B17/B$19 -> 0.00043154601 | G17: =D17/B17 -> 899
A18: Toys & Games | B18: 8 | C18: 8 | D18: 1200 | E18: =D18/D$19 -> 5.1485129e-05 | F18: =B18/B$19 -> 0.00086309203 | G18: =D18/B18 -> 150
A19: Total | B19: =SUM(B10:B18) -> 9269 | C19: n/a | D19: =SUM(D10:D18) -> 23307701 | E19: =SUM(E10:E18) -> 1 | F19: =SUM(F10:F18) -> 1 | G19: =D19/B19 -> 2514.5864
A20: Customers are not additive across categories (one customer can buy in several), so the total is left blank.
A23: Orders by price band (query q04)
A24: Price band (₹) | B24: Orders | C24: Revenue (₹) | D24: Order share | E24: Revenue share
A25: Under 500 | B25: 3495 | C25: 998580 | D25: =B25/B$29 -> 0.37706333 | E25: =C25/C$29 -> 0.042843349
A26: 500 - 1,999 | B26: 3561 | C26: 3995762 | D26: =B26/B$29 -> 0.38418384 | E26: =C26/C$29 -> 0.17143526
A27: 2,000 - 9,999 | B27: 1731 | C27: 7885246 | D27: =B27/B$29 -> 0.18675154 | E27: =C27/C$29 -> 0.33831074
A28: 10,000 and above | B28: 482 | C28: 10428114 | D28: =B28/B$29 -> 0.052001295 | E28: =C28/C$29 -> 0.44741065
A29: Total | B29: =SUM(B25:B28) -> 9269 | C29: =SUM(C25:C28) -> 23307702 | D29: =SUM(D25:D28) -> 1 | E29: =SUM(E25:E28) -> 1
A32: Top 10 sub-categories by revenue, 30+ orders (query q03)
A33: Main category | B33: Sub-category | C33: Orders | D33: Revenue (₹) | E33: Avg order value (₹)
A34: Electronics | B34: SmartTelevisions | C34: 287 | D34: 6180177 | E34: =D34/C34 -> 21533.718
A35: Electronics | B35: Smartphones | C35: 217 | D35: 3395869 | E35: =D35/C35 -> 15649.166
A36: Electronics | B36: SmartWatches | C36: 311 | D36: 791951 | E36: =D36/C36 -> 2546.4662
A37: Home & Kitchen | B37: WaterFilters&Purifiers | C37: 96 | D37: 673464 | E37: =D37/C37 -> 7015.25
A38: Home & Kitchen | B38: MixerGrinders | C38: 216 | D38: 649020 | E38: =D38/C38 -> 3004.7222
A39: Home & Kitchen | B39: StorageWaterHeaters | C39: 96 | D39: 607040 | E39: =D39/C39 -> 6323.3333
A40: Home & Kitchen | B40: InstantWaterHeaters | C40: 178 | D40: 433306 | E40: =D40/C40 -> 2434.3034
A41: Home & Kitchen | B41: HEPAAirPurifiers | C41: 32 | D41: 381344 | E41: =D41/C41 -> 11917
A42: Home & Kitchen | B42: FanHeaters | C42: 146 | D42: 380656 | E42: =D42/C42 -> 2607.2329
A43: Electronics | B43: In-Ear | C43: 352 | D43: 355030 | E43: =D43/C43 -> 1008.608

Sheet Customers
A1: Customers
A2: Customer = a reviewer (IDs are hashed). Repeat = 2+ distinct reviews. Customers come from a sample of up to 8 reviews per product, so repeat rates are a floor.
A4: Repeat vs one-time customers (query q05)
A5: Customer type | B5: Customers | C5: Orders | D5: Revenue (₹) | E5: Customer share | F5: Order share | G5: Revenue share | H5: Avg spend per customer (₹)
A6: Repeat (2+ orders) | B6: 202 | C6: 421 | D6: 984149 | E6: =B6/B$8 -> 0.022320442 | F6: =C6/C$8 -> 0.045420218 | G6: =D6/D$8 -> 0.042224197 | H6: =D6/B6 -> 4872.0248
A7: One-time (1 order) | B7: 8848 | C7: 8848 | D7: 22323553 | E7: =B7/B$8 -> 0.97767956 | F7: =C7/C$8 -> 0.95457978 | G7: =D7/D$8 -> 0.9577758 | H7: =D7/B7 -> 2523.0055
A8: Total | B8: =SUM(B6:B7) -> 9050 | C8: =SUM(C6:C7) -> 9269 | D8: =SUM(D6:D7) -> 23307702 | E8: =SUM(E6:E7) -> 1 | F8: =SUM(F6:F7) -> 1 | G8: =SUM(G6:G7) -> 1 | H8: =D8/B8 -> 2575.4367
A11: Orders per customer (query q06)
A12: Orders per customer | B12: Customers | C12: Share of customers
A13: 1 | B13: 8848 | C13: =B13/B$17 -> 0.97767956
A14: 2 | B14: 187 | C14: =B14/B$17 -> 0.020662983
A15: 3 | B15: 14 | C15: =B15/B$17 -> 0.0015469613
A16: 5 | B16: 1 | C16: =B16/B$17 -> 0.00011049724
A17: Total | B17: =SUM(B13:B16) -> 9050 | C17: =SUM(C13:C16) -> 1
A20: Customers buying in 2+ main categories (query q08)
A21: Cross-category customers | B21: All customers | C21: Share
A22: 107 | B22: =B8 -> 9050 | C22: =A22/B22 -> 0.011823204
A25: Where repeat customers buy (query q09)
A26: Main category | B26: Orders by repeat customers | C26: Revenue (₹) | D26: Revenue share
A27: Electronics | B27: 130 | C27: 507113 | D27: =C27/C$33 -> 0.51528071
A28: Home & Kitchen | B28: 113 | C28: 270289 | D28: =C28/C$33 -> 0.27464236
A29: Computers & Accessories | B29: 159 | C29: 201179 | D29: =C29/C$33 -> 0.20441925
A30: Office Products | B30: 13 | C30: 2944 | D30: =C30/C$33 -> 0.002991417
A31: Home Improvement | B31: 4 | C31: 1348 | D31: =C31/C$33 -> 0.0013697113
A32: Musical Instruments | B32: 2 | C32: 1276 | D32: =C32/C$33 -> 0.0012965516
A33: Total | B33: =SUM(B27:B32) -> 421 | C33: =SUM(C27:C32) -> 984149 | D33: =SUM(D27:D32) -> 1

Sheet Products
A1: Products
A2: Variants of one product (colour/size) are collapsed to one listing (see Notes). Est. revenue = ratings received x selling price: a rough lower bound, not real sales.
A4: Top 10 products by ratings received (query q10)
A5: # | B5: Product | C5: Main category | D5: Sub-category | E5: Price (₹) | F5: Discount % | G5: Rating | H5: Ratings received
A6: 1 | B6: Amazon Basics High-Speed HDMI Cable, 6 Feet… | C6: Electronics | D6: HDMICables | E6: 309 | F6: 0.35 | G6: 4.4 | H6: 426973
A7: 2 | B7: boAt Bassheads 100 in Ear Wired Earphones with… | C7: Electronics | D7: In-Ear | E7: 379 | F7: 0.62 | G7: 4.1 | H7: 363713
A8: 3 | B8: Redmi 9 Activ (Carbon Black, 4GB RAM, 64GB Sto… | C8: Electronics | D8: Smartphones | E8: 8499 | F8: 0.23 | G8: 4.1 | H8: 313836
A9: 4 | B9: boAt Bassheads 225 in Ear Wired Earphones with… | C9: Electronics | D9: In-Ear | E9: 699 | F9: 0.3 | G9: 4.1 | H9: 273189
A10: 5 | B10: Pigeon Polypropylene Mini Handy and Compact Ch… | C10: Home & Kitchen | D10: Choppers | E10: 199 | F10: 0.6 | G10: 4.1 | H10: 270563
A11: 6 | B11: SanDisk Cruzer Blade 32GB USB Flash Drive | C11: Computers & Accessories | D11: PenDrives | E11: 289 | F11: 0.56 | G11: 4.3 | H11: 253105
A12: 7 | B12: SanDisk Extreme SD UHS I 64GB Card for 4K Vide… | C12: Electronics | D12: MicroSD | E12: 939 | F12: 0.48 | G12: 4.5 | H12: 205052
A13: 8 | B13: JBL C100SI Wired In Ear Headphones with Mic, J… | C13: Electronics | D13: In-Ear | E13: 599 | F13: 0.4 | G13: 4.1 | H13: 192590
A14: 9 | B14: SanDisk Ultra Dual 64 GB USB 3.0 OTG Pen Drive… | C14: Computers & Accessories | D14: PenDrives | E14: 579 | F14: 0.59 | G14: 4.3 | H14: 189104
A15: 10 | B15: boAt Airdopes 121v2 in-Ear True Wireless Earbu… | C15: Electronics | D15: In-Ear | E15: 1299 | F15: 0.57 | G15: 3.8 | H15: 180998
A18: Top 10 products by estimated revenue (query q11)
A19: # | B19: Product | C19: Main category | D19: Price (₹) | E19: Rating | F19: Ratings received | G19: Est. revenue (₹ crore)
A20: 1 | B20: Redmi 9 Activ (Carbon Black, 4GB RAM, 64GB Sto… | C20: Electronics | D20: 8499 | E20: 4.1 | F20: 313836 | G20: =D20*F20/10000000 -> 266.72922
A21: 2 | B21: Redmi 126 cm (50 inches) 4K Ultra HD Android S… | C21: Electronics | D21: 32999 | E21: 4.2 | F21: 45238 | G21: =D21*F21/10000000 -> 149.28088
A22: 3 | B22: Samsung Galaxy S20 FE 5G (Cloud Navy, 8GB RAM… | C22: Electronics | D22: 37990 | E22: 4.2 | F22: 27790 | G22: =D22*F22/10000000 -> 105.57421
A23: 4 | B23: MI 138.8 cm (55 inches) 5X Series 4K Ultra HD… | C23: Electronics | D23: 46999 | E23: 4.3 | F23: 21252 | G23: =D23*F23/10000000 -> 99.882275
A24: 5 | B24: OnePlus 108 cm (43 inches) Y Series Full HD Sm… | C24: Electronics | D24: 24999 | E24: 4.2 | F24: 34899 | G24: =D24*F24/10000000 -> 87.24401
A25: 6 | B25: MI 108 cm (43 inches) 5A Series Full HD Smart… | C25: Electronics | D25: 24999 | E25: 4.2 | F25: 32840 | G25: =D25*F25/10000000 -> 82.096716
A26: 7 | B26: OPPO A31 (Mystery Black, 6GB RAM, 128GB Storag… | C26: Electronics | D26: 12490 | E26: 4.2 | F26: 58506 | G26: =D26*F26/10000000 -> 73.073994
A27: 8 | B27: Samsung Galaxy M32 Prime Edition (Light Blue… | C27: Electronics | D27: 12999 | E27: 4.1 | F27: 56098 | G27: =D27*F27/10000000 -> 72.92179
A28: 9 | B28: Redmi Note 11 (Space Black, 4GB RAM, 64GB Stor… | C28: Electronics | D28: 12999 | E28: 4.1 | F28: 50772 | G28: =D28*F28/10000000 -> 65.998523
A29: 10 | B29: Redmi Note 11 Pro + 5G (Stealth Black, 8GB RAM… | C29: Electronics | D29: 22999 | E29: 3.9 | F29: 25824 | G29: =D29*F29/10000000 -> 59.392618
A32: Estimated revenue by main category (query q12)
A33: Main category | B33: Product families | C33: Ratings received | D33: Est. revenue (₹) | E33: Est. revenue (₹ crore) | F33: Est. revenue share
A34: Electronics | B34: 379 | C34: 8392719 | D34: 28068265871 | E34: =D34/10000000 -> 2806.8266 | F34: =D34/D$43 -> 0.70389832
A35: Home & Kitchen | B35: 447 | C35: 2989267 | D35: 6262175578 | E35: =D35/10000000 -> 626.21756 | F35: =D35/D$43 -> 0.15704336
A36: Computers & Accessories | B36: 321 | C36: 4939800 | D36: 5424168825 | E36: =D36/10000000 -> 542.41688 | F36: =D36/D$43 -> 0.13602776
A37: Musical Instruments | B37: 2 | C37: 88882 | D37: 64458076 | E37: =D37/10000000 -> 6.4458076 | F37: =D37/D$43 -> 0.001616485
A38: Office Products | B38: 30 | C38: 146614 | D38: 45511240 | E38: =D38/10000000 -> 4.551124 | F38: =D38/D$43 -> 0.0011413347
A39: Health & Personal Care | B39: 1 | C39: 3663 | D39: 3293037 | E39: =D39/10000000 -> 0.3293037 | F39: =D39/D$43 -> 8.2583058e-05
A40: Car & Motorbike | B40: 1 | C40: 1118 | D40: 2615002 | E40: =D40/10000000 -> 0.2615002 | F40: =D40/D$43 -> 6.5579239e-05
A41: Home Improvement | B41: 2 | C41: 8566 | D41: 2587190 | E41: =D41/10000000 -> 0.258719 | F41: =D41/D$43 -> 6.4881768e-05
A42: Toys & Games | B42: 1 | C42: 15867 | D42: 2380050 | E42: =D42/10000000 -> 0.238005 | F42: =D42/D$43 -> 5.9687093e-05
A43: Total | B43: =SUM(B34:B42) -> 1184 | C43: =SUM(C34:C42) -> 16586496 | D43: =SUM(D34:D42) -> 39875454869 | E43: =D43/10000000 -> 3987.5455 | F43: =SUM(F34:F42) -> 1
A46: Discount depth vs ratings received (query q14)
A47: Discount band | B47: Products | C47: Avg ratings per product | D47: Avg rating
...

Sheet Notes
A1: Notes: method and caveats
A3: Topic | B3: Note
A4: Data | B4: Kaggle 'Amazon Sales Dataset' (karkavelrajaj), scraped from Amazon India; CC BY-NC-SA 4.0. 1,351 unique products, each with up to 8 sampled customer reviews.
A5: What an 'order' is | B5: The data has no order table. One order = one distinct review (review_id). A review attached to several variants of the same product is counted once. Orders are therefore a sample, capped at ~8 per listing, not real purchases.
A6: What 'revenue' is | B6: Selling price of the ordered item, summed over orders. It is a sample-based proxy; absolute amounts are NOT company revenue. Use the shares, not the rupee totals.
A7: Customers | B7: A customer is a reviewer. IDs are hashed (SHA-256, truncated) and names and review text are not stored. Because only ~8 reviews per product are present, repeat-customer rates are a floor, not the true rate.
A8: Estimated revenue | B8: Ratings received x selling price. Only some buyers leave a rating, so this is a lower bound, and it uses today's price for all past ratings.
A9: Product families | B9: Many listings are variants (colour/size) with near-identical rating counts. Listings with 1,000+ ratings are merged when they share sub-category, star rating and rating_count/100. This is an approximation and may occasionally merge unrelated products or miss a variant.
A10: Colour legend | B10: Blue = value copied from a SQL query result. Black = Excel formula (shares, averages, totals, headline findings).
A11: Rebuild | B11: python load_db.py -> python run_queries.py -> python build_excel.py. All SQL is in sql/queries.sql.
